Workbook

Sheet Couverture
A1: FICHE TECHNIQUE — COUVERTURE
A2: Une page qui permet à l’usine de classer votre modèle, de le chiffrer et de retrouver la bonne version plus tard. Conservez la référence sur tous les documents par la suite.
A4: Champ | B4: Votre réponse | C4: Exemple
A5: Référence modèle | C5: HLN-2401-HOOD
A6: Nom et catégorie | C6: Sweat oversize, unisexe
A7: Saison et délai de livraison | C7: AH26, en boutique en août
A8: Marque et contact | C8: marque@exemple.com
A9: Quantité cible | C9: 300 pièces, 3 coloris
A10: Version et date | C10: v3, 12 mai 2026
A11: Prix de vente cible | C11: 79 US$
A13: Prête à envoyer ? Joignez ce fichier à une demande de devis sur hlnapparel.com/fr/contact. Nous répondons avec un devis chiffré et un plan d’échantillonnage, généralement en moins de cinq heures.

Sheet Croquis
A1: FICHE TECHNIQUE — CROQUIS
A2: Un dessin évite plus de malentendus que n’importe quel paragraphe. Un tracé à plat, une photo annotée ou un vêtement de référence conviennent ; ce sont les notes qui les accompagnent qui les rendent utiles.
A4: VUE DE FACE — collez ou dessinez le dessin à plat
A15: VUE DE DOS — collez ou dessinez le dessin à plat
A27: # | B27: Détail — ce que désigne chaque numéro du croquis
A28: 1
A29: 2
A30: 3
A31: 4
A32: 5
A33: 6
A34: 7
A35: 8
A36: 9
A37: 10
A38: ex. 1 : capuche doublée

Sheet Nomenclature
A1: FICHE TECHNIQUE — NOMENCLATURE
A2: La nomenclature est l’endroit où se fabrique le prix. Détaillez chaque partie séparément — tissu principal, bord-côte, accessoires, étiquettes, emballage — avec les colonnes ci-dessous. Le besoin par pièce et les références de couleur permettent au fournisseur de chiffrer deux fois la même chose.
A4: Pièce | B4: Matière | C4: Composition | D4: Grammage (g/m²) | E4: Couleur | F4: Fournisseur ou Pantone | G4: Consommation / pièce | H4: Notes
A5: ex. Corps | B5: Molleton gratté | C5: 80 % coton / 20 % polyester | D5: 320 GSM | E5: Pantone 19-4024 TPX | F5: échantillon envoyé le 12 mai | G5: 1,4 m par pièce | H5: Lavage enzymatique, retrait max. 5 %

Sheet Mesures
A1: FICHE TECHNIQUE — MESURES
A2: Le vêtement est contrôlé à partir de cet onglet : il doit donc être sans ambiguïté. Une ligne par mesure, une colonne par taille et une tolérance. C’est la feuille qui évite de refuser une livraison pour 1 cm d’écart.
A3: Type de vêtement | B3: Sweat à capuche / sweat-shirt | C3: Unité | D3: cm | E3: Choisissez un type de vêtement pour charger ses points de mesure, puis modifiez n’importe quelle cellule. Les tolérances sont des valeurs de départ courantes ; fixez les valeurs définitives par modèle.
A4: Point de mesure | B4: Méthode de mesure | C4: =IFERROR(INDEX('POM library'!$B$2:$G$91,MATCH($B$3&"|sizes",'POM library'!$A$2:$A$91,0),1)&"","") -> XS | D4: =IFERROR(INDEX('POM library'!$B$2:$G$91,MATCH($B$3&"|sizes",'POM library'!$A$2:$A$91,0),2)&"","") -> S | E4: =IFERROR(INDEX('POM library'!$B$2:$G$91,MATCH($B$3&"|sizes",'POM library'!$A$2:$A$91,0),3)&"","") -> M | F4: =IFERROR(INDEX('POM library'!$B$2:$G$91,MATCH($B$3&"|sizes",'POM library'!$A$2:$A$91,0),4)&"","") -> L | G4: =IFERROR(INDEX('POM library'!$B$2:$G$91,MATCH($B$3&"|sizes",'POM library'!$A$2:$A$91,0),5)&"","") -> XL | H4: =IFERROR(INDEX('POM library'!$B$2:$G$91,MATCH($B$3&"|sizes",'POM library'!$A$2:$A$91,0),6)&"","") -> XXL | I4: Tolérance ±
A5: =IFERROR(INDEX('POM library'!$B$2:$B$91,MATCH($B$3&"|1",'POM library'!$A$2:$A$91,0)),"") -> Largeur poitrine | B5: =IFERROR(INDEX('POM library'!$C$2:$C$91,MATCH($B$3&"|1",'POM library'!$A$2:$A$91,0)),"") -> À 2,5 cm sous l’emmanchure, à plat, bord à bord | I5: =IFERROR(INDEX('POM library'!$D$2:$D$91,MATCH($B$3&"|1",'POM library'!$A$2:$A$91,0)),"") -> 1
A6: =IFERROR(INDEX('POM library'!$B$2:$B$91,MATCH($B$3&"|2",'POM library'!$A$2:$A$91,0)),"") -> Longueur corps depuis HPS | B6: =IFERROR(INDEX('POM library'!$C$2:$C$91,MATCH($B$3&"|2",'POM library'!$A$2:$A$91,0)),"") -> Du point haut d’épaule, droit jusqu’au bas | I6: =IFERROR(INDEX('POM library'!$D$2:$D$91,MATCH($B$3&"|2",'POM library'!$A$2:$A$91,0)),"") -> 1
A7: =IFERROR(INDEX('POM library'!$B$2:$B$91,MATCH($B$3&"|3",'POM library'!$A$2:$A$91,0)),"") -> Largeur d’épaules | B7: =IFERROR(INDEX('POM library'!$C$2:$C$91,MATCH($B$3&"|3",'POM library'!$A$2:$A$91,0)),"") -> D’une couture d’épaule à l’autre, droit sur le dos | I7: =IFERROR(INDEX('POM library'!$D$2:$D$91,MATCH($B$3&"|3",'POM library'!$A$2:$A$91,0)),"") -> 1
A8: =IFERROR(INDEX('POM library'!$B$2:$B$91,MATCH($B$3&"|4",'POM library'!$A$2:$A$91,0)),"") -> Longueur manche depuis milieu dos | B8: =IFERROR(INDEX('POM library'!$C$2:$C$91,MATCH($B$3&"|4",'POM library'!$A$2:$A$91,0)),"") -> Du milieu dos de l’encolure, par l’épaule, jusqu’au poignet | I8: =IFERROR(INDEX('POM library'!$D$2:$D$91,MATCH($B$3&"|4",'POM library'!$A$2:$A$91,0)),"") -> 1
A9: =IFERROR(INDEX('POM library'!$B$2:$B$91,MATCH($B$3&"|5",'POM library'!$A$2:$A$91,0)),"") -> Emmanchure (droite) | B9: =IFERROR(INDEX('POM library'!$C$2:$C$91,MATCH($B$3&"|5",'POM library'!$A$2:$A$91,0)),"") -> Du point d’épaule, droit jusqu’à la couture sous le bras | I9: =IFERROR(INDEX('POM library'!$D$2:$D$91,MATCH($B$3&"|5",'POM library'!$A$2:$A$91,0)),"") -> 0.5
A10: =IFERROR(INDEX('POM library'!$B$2:$B$91,MATCH($B$3&"|6",'POM library'!$A$2:$A$91,0)),"") -> Largeur biceps | B10: =IFERROR(INDEX('POM library'!$C$2:$C$91,MATCH($B$3&"|6",'POM library'!$A$2:$A$91,0)),"") -> À 2,5 cm sous l’emmanchure, perpendiculaire au pli de manche | I10: =IFERROR(INDEX('POM library'!$D$2:$D$91,MATCH($B$3&"|6",'POM library'!$A$2:$A$91,0)),"") -> 0.5
A11: =IFERROR(INDEX('POM library'!$B$2:$B$91,MATCH($B$3&"|7",'POM library'!$A$2:$A$91,0)),"") -> Largeur du bas (au repos) | B11: =IFERROR(INDEX('POM library'!$C$2:$C$91,MATCH($B$3&"|7",'POM library'!$A$2:$A$91,0)),"") -> Bord-côte du bas, bord à bord, sans étirer | I11: =IFERROR(INDEX('POM library'!$D$2:$D$91,MATCH($B$3&"|7",'POM library'!$A$2:$A$91,0)),"") -> 1
A12: =IFERROR(INDEX('POM library'!$B$2:$B$91,MATCH($B$3&"|8",'POM library'!$A$2:$A$91,0)),"") -> Largeur poignet (au repos) | B12: =IFERROR(INDEX('POM library'!$C$2:$C$91,MATCH($B$3&"|8",'POM library'!$A$2:$A$91,0)),"") -> Ouverture du poignet, bord à bord, sans étirer | I12: =IFERROR(INDEX('POM library'!$D$2:$D$91,MATCH($B$3&"|8",'POM library'!$A$2:$A$91,0)),"") -> 0.5
A13: =IFERROR(INDEX('POM library'!$B$2:$B$91,MATCH($B$3&"|9",'POM library'!$A$2:$A$91,0)),"") -> Hauteur de capuche | B13: =IFERROR(INDEX('POM library'!$C$2:$C$91,MATCH($B$3&"|9",'POM library'!$A$2:$A$91,0)),"") -> De la couture d’encolure au HPS jusqu’au sommet de la capuche | I13: =IFERROR(INDEX('POM library'!$D$2:$D$91,MATCH($B$3&"|9",'POM library'!$A$2:$A$91,0)),"") -> 1
A14: =IFERROR(INDEX('POM library'!$B$2:$B$91,MATCH($B$3&"|10",'POM library'!$A$2:$A$91,0)),"") -> Largeur de capuche | B14: =IFERROR(INDEX('POM library'!$C$2:$C$91,MATCH($B$3&"|10",'POM library'!$A$2:$A$91,0)),"") -> Point le plus large de la capuche, à plat | I14: =IFERROR(INDEX('POM library'!$D$2:$D$91,MATCH($B$3&"|10",'POM library'!$A$2:$A$91,0)),"") -> 1
A15: =IFERROR(INDEX('POM library'!$B$2:$B$91,MATCH($B$3&"|11",'POM library'!$A$2:$A$91,0)),"") -> Ouverture de poche | B15: =IFERROR(INDEX('POM library'!$C$2:$C$91,MATCH($B$3&"|11",'POM library'!$A$2:$A$91,0)),"") -> Bord à bord le long de l’ouverture | I15: =IFERROR(INDEX('POM library'!$D$2:$D$91,MATCH($B$3&"|11",'POM library'!$A$2:$A$91,0)),"") -> 0.5
A16: =IFERROR(INDEX('POM library'!$B$2:$B$91,MATCH($B$3&"|12",'POM library'!$A$2:$A$91,0)),"") -> Position de poche | B16: =IFERROR(INDEX('POM library'!$C$2:$C$91,MATCH($B$3&"|12",'POM library'!$A$2:$A$91,0)),"") -> Du HPS jusqu’au haut de la poche | I16: =IFERROR(INDEX('POM library'!$D$2:$D$91,MATCH($B$3&"|12",'POM library'!$A$2:$A$91,0)),"") -> 0.5
A17: =IFERROR(INDEX('POM library'!$B$2:$B$91,MATCH($B$3&"|13",'POM library'!$A$2:$A$91,0)),"") | B17: =IFERROR(INDEX('POM library'!$C$2:$C$91,MATCH($B$3&"|13",'POM library'!$A$2:$A$91,0)),"") | I17: =IFERROR(INDEX('POM library'!$D$2:$D$91,MATCH($B$3&"|13",'POM library'!$A$2:$A$91,0)),"")
A18: =IFERROR(INDEX('POM library'!$B$2:$B$91,MATCH($B$3&"|14",'POM library'!$A$2:$A$91,0)),"") | B18: =IFERROR(INDEX('POM library'!$C$2:$C$91,MATCH($B$3&"|14",'POM library'!$A$2:$A$91,0)),"") | I18: =IFERROR(INDEX('POM library'!$D$2:$D$91,MATCH($B$3&"|14",'POM library'!$A$2:$A$91,0)),"")

Sheet Montage
A1: FICHE TECHNIQUE — MONTAGE
A2: Cet onglet transforme un bon échantillon en commande reproductible. Décrivez points, coutures, fil et décoration avec précision ; tout ce qui reste flou sera décidé par la personne devant la machine.
A4: Champ | B4: Spécification | C4: Exemple
A5: Type et densité de point | C5: Point droit, 12 SPI
A6: Type et finition de couture | C6: Épaules rubanées
A7: Fil | C7: Tex 30, ton sur ton
A8: Position et taille d’impression | C8: Face, 28 × 20 cm, 3 couleurs
A9: Position et nombre de points de broderie | C9: Poitrine gauche, ~4 500 points
A10: Quincaillerie | C10: YKK n° 5, sans nickel
A11: Surpiqûres | C11: 2 mm, ton sur ton

Sheet Étiquettes et emballage
A1: FICHE TECHNIQUE — ÉTIQUETTES ET EMBALLAGE
A2: C’est ici que vit la marque : les accessoires et impressions qui portent votre nom, et le carton dans lequel la marchandise arrive.
A4: Champ | B4: Spécification | C4: Exemple
A5: Étiquette principale | C5: Tissée, milieu dos
A6: Étiquette d’entretien | C6: FR/EN/ES, couture latérale
A7: Étiquette volante | C7: Carton mat, cordon noir
A8: Pliage et sachet | C8: Papier de soie, sachet PE recyclé
A9: Code-barres ou autocollants | C9: UPC-A
A10: Emballage carton | C10: 50 pièces, tailles assorties

Sheet Coloris
A1: FICHE TECHNIQUE — COLORIS
A2: La couleur est la première cause de surprise sur le tissu en production. Nommez chaque coloris, rattachez-le à une référence physique et indiquez le nombre de pièces qu’il porte.
A4: Champ | B4: Plan | C4: Exemple
A5: Nom du coloris | C5: Vert océan
A6: Référence couleur | C6: Pantone 17-5117 TPX
A7: Quantité par coloris | C7: 120 / 100 / 80
A8: Répartition par taille | C8: S–XXL, 20 % / 30 % / 30 % / 20 %
A9: Accessoires assortis | C9: Bord-côte et cordon ton sur ton
A10: Réassorts et best-sellers | C10: Le vert océan est la couleur phare

Sheet POM library
A1: key | B1: Point de mesure | C1: Méthode de mesure | D1: Tolérance ±
A2: Sweat à capuche / sweat-shirt|sizes | B2: XS | C2: S | D2: M | E2: L | F2: XL | G2: XXL
A3: Sweat à capuche / sweat-shirt|1 | B3: Largeur poitrine | C3: À 2,5 cm sous l’emmanchure, à plat, bord à bord | D3: 1
A4: Sweat à capuche / sweat-shirt|2 | B4: Longueur corps depuis HPS | C4: Du point haut d’épaule, droit jusqu’au bas | D4: 1
A5: Sweat à capuche / sweat-shirt|3 | B5: Largeur d’épaules | C5: D’une couture d’épaule à l’autre, droit sur le dos | D5: 1
A6: Sweat à capuche / sweat-shirt|4 | B6: Longueur manche depuis milieu dos | C6: Du milieu dos de l’encolure, par l’épaule, jusqu’au poignet | D6: 1
A7: Sweat à capuche / sweat-shirt|5 | B7: Emmanchure (droite) | C7: Du point d’épaule, droit jusqu’à la couture sous le bras | D7: 0.5
A8: Sweat à capuche / sweat-shirt|6 | B8: Largeur biceps | C8: À 2,5 cm sous l’emmanchure, perpendiculaire au pli de manche | D8: 0.5
A9: Sweat à capuche / sweat-shirt|7 | B9: Largeur du bas (au repos) | C9: Bord-côte du bas, bord à bord, sans étirer | D9: 1
A10: Sweat à capuche / sweat-shirt|8 | B10: Largeur poignet (au repos) | C10: Ouverture du poignet, bord à bord, sans étirer | D10: 0.5
A11: Sweat à capuche / sweat-shirt|9 | B11: Hauteur de capuche | C11: De la couture d’encolure au HPS jusqu’au sommet de la capuche | D11: 1
A12: Sweat à capuche / sweat-shirt|10 | B12: Largeur de capuche | C12: Point le plus large de la capuche, à plat | D12: 1
A13: Sweat à capuche / sweat-shirt|11 | B13: Ouverture de poche | C13: Bord à bord le long de l’ouverture | D13: 0.5
A14: Sweat à capuche / sweat-shirt|12 | B14: Position de poche | C14: Du HPS jusqu’au haut de la poche | D14: 0.5
A15: T-shirt / polo|sizes | B15: XS | C15: S | D15: M | E15: L | F15: XL | G15: XXL
A16: T-shirt / polo|1 | B16: Largeur poitrine | C16: À 2,5 cm sous l’emmanchure, à plat, bord à bord | D16: 1
A17: T-shirt / polo|2 | B17: Longueur corps depuis HPS | C17: Du point haut d’épaule, droit jusqu’au bas | D17: 1
A18: T-shirt / polo|3 | B18: Largeur d’épaules | C18: D’une couture d’épaule à l’autre, droit sur le dos | D18: 1
A19: T-shirt / polo|4 | B19: Longueur de manche | C19: De la couture d’épaule au bas de manche, le long du pli supérieur | D19: 0.5
A20: T-shirt / polo|5 | B20: Ouverture de manche | C20: Bas de manche, bord à bord | D20: 0.5
A21: T-shirt / polo|6 | B21: Emmanchure (droite) | C21: Du point d’épaule, droit jusqu’à la couture sous le bras | D21: 0.5
A22: T-shirt / polo|7 | B22: Largeur du bas | C22: Bas du vêtement, bord à bord | D22: 1
A23: T-shirt / polo|8 | B23: Largeur d’encolure | C23: D’une couture d’encolure à l’autre au HPS | D23: 0.5
A24: T-shirt / polo|9 | B24: Profondeur d’encolure devant | C24: De la ligne HPS à la couture d’encolure devant | D24: 0.5
A25: T-shirt / polo|10 | B25: Profondeur d’encolure dos | C25: De la ligne HPS à la couture d’encolure dos | D25: 0.3
A26: T-shirt / polo|11 | B26: Largeur bord-côte / col | C26: Hauteur du bord-côte ou du col fini au milieu dos | D26: 0.2
A27: T-shirt / polo|12 | B27: Longueur de patte (polo) | C27: Du haut de la patte à la piqûre du bas | D27: 0.5
A28: Veste|sizes | B28: XS | C28: S | D28: M | E28: L | F28: XL | G28: XXL
A29: Veste|1 | B29: Largeur poitrine | C29: À 2,5 cm sous l’emmanchure, fermé, à plat | D29: 1
A30: Veste|2 | B30: Longueur corps depuis milieu dos | C30: De la couture d’encolure milieu dos jusqu’au bas | D30: 1
A31: Veste|3 | B31: Largeur d’épaules | C31: D’une couture d’épaule à l’autre, droit sur le dos | D31: 1
A32: Veste|4 | B32: Longueur manche depuis milieu dos | C32: Du milieu dos de l’encolure, par l’épaule, jusqu’au poignet | D32: 1
A33: Veste|5 | B33: Emmanchure (droite) | C33: Du point d’épaule, droit jusqu’à la couture sous le bras | D33: 0.5
A34: Veste|6 | B34: Largeur biceps | C34: À 2,5 cm sous l’emmanchure, perpendiculaire au pli de manche | D34: 0.5
A35: Veste|7 | B35: Ouverture du poignet | C35: Poignet, bord à bord, fermé | D35: 0.5
A36: Veste|8 | B36: Largeur du bas | C36: Bas du vêtement, fermé, bord à bord | D36: 1
A37: Veste|9 | B37: Hauteur de col milieu dos | C37: De la couture au bord du col au milieu dos | D37: 0.3
A38: Veste|10 | B38: Longueur de zip devant | C38: Dents du zip, de l’arrêt haut à l’arrêt bas | D38: 0.5
A39: Veste|11 | B39: Ouverture de poche | C39: Bord à bord le long de l’ouverture | D39: 0.5
A40: Pantalon / jogging|sizes | B40: XS | C40: S | D40: M | E40: L | F40: XL | G40: XXL
...
